Workbook

Sheet Locations
A1: State | B1: City | C1: Store Name | D1: Street Address | E1: ZIP | F1: Phone | G1: Website / Location Page
A2: AL | B2: Cullman | C2: BoxDrop Cullman | D2: 1633 2nd Ave NW | E2: 35055 | F2: (256) 600-0180 | G2: https://boxdropdirect.com/pages/location/cullman
A3: AL | B3: Decatur | C3: BoxDrop Decatur | D3: 231 Grant Street Southeast | F3: (256) 456-5400 | G3: https://boxdropdirect.com/pages/location/box-drop-decatur
A4: AL | B4: Dothan | C4: Boxdrop Dothan | D4: 1357 Fortner St | E4: 36301 | F4: (334) 392-4200 | G4: https://boxdropdirect.com/pages/location/dothan
A5: AL | B5: Enterprise | C5: Enterprise Alabama | D5: 621 Boll Weevil Circle Suite 27 | E5: 36330 | F5: (334) 392-4200 | G5: https://boxdropdirect.com/pages/location/enterprise-alabama
A6: AL | B6: Huntsville | C6: BoxDrop Huntsville | D6: 2801 Newby Rd SW Ste A | F6: (256) 627-7811 | G6: https://boxdropdirect.com/pages/location/huntsville-al
A7: AL | B7: Mobile | C7: Boxdrop North Mobile | D7: 4130 Government Blvd Suite C | F7: (251) 373-0047 | G7: https://boxdropdirect.com/pages/location/north-mobile
A8: AL | B8: Montgomery | C8: Boxdrop Montgomery Mattress Clearance Center | D8: 5325 Wares Ferry Road Unit F | E8: 36109 | F8: (334) 440-5660 | G8: https://boxdropdirect.com/pages/location/montgomery-mattress-clearance-center
A9: AL | B9: Rogersville | C9: BoxDrop Rogersville | D9: 16487 Hwy 72 | E9: 35652 | F9: (256) 600-0153 | G9: https://boxdropdirect.com/pages/location/rogersville
A10: AR | B10: Hot Springs | C10: BoxDrop Hot Springs Arkansas | D10: 619 Albert Pike Road | E10: 71913 | F10: (501) 620-0173 | G10: https://boxdropdirect.com/pages/location/hot-springs-arkansas
A11: AR | B11: Jonesboro | C11: Nea Mattress Direct and Furniture | D11: 6701 Johnson Avenue | E11: 72405 | F11: (501) 454-5613 | G11: https://boxdropdirect.com/pages/location/nea-mattress-direct-and-furniture
A12: AR | B12: Mountain View | C12: BoxDrop Mountain View | D12: 417 Sylamore Avenue | E12: 72560 | F12: (870) 213-6700 | G12: https://boxdropdirect.com/pages/location/mountain-view
A13: AZ | B13: El Mirage | C13: BoxDrop El Mirage | D13: 8552 N Dysart Rd #200a | E13: 85335 | F13: (623) 271-4320 | G13: https://boxdropdirect.com/pages/location/el-mirage
A14: AZ | B14: Green Valley | C14: Box Drop South Tucson | D14: 115 West Esperanza Boulevard Ste 115D | E14: 85614 | F14: (520) 399-6514 | G14: https://boxdropdirect.com/pages/location/box-drop-south-tucson
A15: AZ | B15: Lake Havasu City | C15: BoxDrop Lake Havasu | D15: 621 N Lake Havasu Ave | F15: (928) 302-6647 | G15: https://boxdropdirect.com/pages/location/box-drop-lake-havasu
A16: AZ | B16: Prescott | C16: BoxDrop Prescott | D16: 6724 Corsair Ave Unit-5 | E16: 86301 | F16: (928) 642-2905 | G16: https://boxdropdirect.com/pages/location/prescott
A17: AZ | B17: Yuma | C17: BoxDrop Yuma | D17: 12585 S Frontage Rd | E17: 85367 | F17: (928) 920-8609 | G17: https://boxdropdirect.com/pages/location/yuma
A18: CA | B18: Bakersfield | C18: BoxDrop Bakersfield | D18: 2809 Unicorn Road #104 | E18: 93308 | F18: (661) 699-2615 | G18: https://boxdropdirect.com/pages/location/bakersfield
A19: CA | B19: Brawley | C19: BoxDrop Mattress & Furniture Imperial Valley | D19: 623 Main St | E19: 92227 | F19: (760) 442-2582 | G19: https://boxdropdirect.com/pages/location/mattress-furniture-imperial-valley
A20: CA | B20: City of Industry | C20: BoxDrop City of Industry | D20: 15805 Valley Blvd | F20: (562) 548-1524 | G20: https://boxdropdirect.com/pages/location/cityofindustry-ca
A21: CA | B21: El Cajon | C21: Box Drop of El Cajon | D21: 762 N Johnson Ave, Suite 101 | E21: 91901 | F21: (619) 560-6957 | G21: https://boxdropdirect.com/pages/location/box-drop-of-el-cajon
A22: CA | B22: Grass Valley | C22: BoxDrop Grassvalley | D22: 504 Whiting St | E22: 95945 | F22: (530) 320-4648 | G22: https://boxdropdirect.com/pages/location/grassvalley
A23: CA | B23: Placerville | C23: BoxDrop Placerville | D23: 337 Industrial Dr Unit #2 | E23: 95667 | F23: (530) 553-0333 | G23: https://boxdropdirect.com/pages/location/placerville
A24: CA | B24: Redding | C24: BoxDrop Redding | D24: 940 Wall St | E24: 96002 | F24: (530) 395-1133 | G24: https://boxdropdirect.com/pages/location/box-drop-redding
A25: CA | B25: Susanville | C25: BoxDrop Susanville | D25: 911 Main St | E25: 96130 | F25: (530) 260-4600 | G25: https://boxdropdirect.com/pages/location/susanville
A26: CA | B26: Victorville | C26: BoxDrop Mattress Victorville | D26: 15354 Bonanza Td. Unit B | E26: 92392 | F26: (760) 617-8559 | G26: https://www.facebook.com/BoxDropVictorville
A27: CA | B27: Visalia | C27: Visalia BoxDrop Mattress & Furniture | D27: 4243 W. Noble Ave. | E27: 93277 | F27: (559) 429-4731 | G27: https://boxdropdirect.com/pages/location/visalia-mattress-furniture
A28: CO | B28: Castle Rock | C28: BoxDrop Castle Rock | D28: 2811 U.S. 85 | E28: 80109 | F28: (720) 595-7578 | G28: https://boxdropdirect.com/pages/location/box-drop-castle-rock
A29: CO | B29: Denver | C29: Boxdrop Denver Central | D29: 4665 Paris St A140 | E29: 80239 | F29: (720) 793-6287 | G29: https://boxdropdirect.com/pages/location/denver-central
A30: CO | B30: Pueblo | C30: Boxdrop Pueblo | D30: 1318 E US 50 bypass | E30: 81001 | F30: (719) 820-5524 | G30: https://boxdropdirect.com/pages/location/pueblo
A31: CT | B31: East Windsor | C31: BoxDrop Mattress Outlet by Jimmy | D31: 7 Thompson Rd. | E31: 06088 | F31: (860) 709-7667 | G31: https://mattressesbyjimmy.com
A32: CT | B32: Montville | C32: BoxDrop Montville Mattress and Furniture | D32: 2020 Norwich New London Tpke | E32: 06382 | F32: (203) 751-4512 | G32: https://boxdropdirect.com/pages/location/montville-mattress-and-furniture
... A45: FL | B45: Tallahassee | C45: Boxdrop Tallahassee Furniture Direct | D45: 2855 Industrial Plaza Drive | E45: 32301 | F45: (850) 545-7112 | G45: https://boxdropdirect.com/pages/location/tallahassee-furniture-direct
A46: FL | B46: Tampa | C46: Boxdrop North Tampa | D46: 924 East 124th Avenue Unit A | F46: (813) 993-9863 | G46: https://boxdropdirect.com/pages/location/north-tampa
A47: FL | B47: Yulee | C47: BoxDrop Yulee | D47: 96064 Victoria's Place | E47: 32097 | F47: (904) 773-4448 | G47: https://boxdropdirect.com/pages/location/yulee
A48: GA | B48: Dallas | C48: Boxdrop Mattress Direct-Dallas, GA | D48: 185 East Paulding Drive Suite 104 | E48: 30157 | F48: (678) 752-1818 | G48: https://boxdropdirect.com/pages/location/mattress-direct-dallas-ga
A49: GA | B49: Douglas | C49: BoxDrop Douglas | D49: 823 Peterson Ave South | F49: (912) 493-0866 | G49: https://boxdropdirect.com/pages/location/douglas-ga
A50: GA | B50: Martinez | C50: BoxDrop Clearance Center of Augusta | D50: 3830 Washington Rd Ste 31 | E50: 30909 | F50: (762) 994-6715 | G50: https://boxdropdirect.com/pages/location/clearance-center-of-augusta
A51: GA | B51: Stone Mountain | C51: Atlanta Furniture Direct | D51: 4611 Greer Circle | E51: 30083 | F51: (404) 824-4896 | G51: https://boxdropdirect.com/pages/location/atlanta-furniture-direct
A52: GA | B52: Tifton | C52: BoxDrop Tifton | D52: 163 Virginia Ave South Suite D | E52: 31794 | F52: (229) 598-9999 | G52: https://boxdropdirect.com/pages/location/tifton
...

Sheet By State
A1: State | B1: Locations
A2: AL | B2: =COUNTIF(Locations!A:A,A2) -> 8
A3: AR | B3: =COUNTIF(Locations!A:A,A3) -> 3
A4: AZ | B4: =COUNTIF(Locations!A:A,A4) -> 5
A5: CA | B5: =COUNTIF(Locations!A:A,A5) -> 10
A6: CO | B6: =COUNTIF(Locations!A:A,A6) -> 3
A7: CT | B7: =COUNTIF(Locations!A:A,A7) -> 2
A8: FL | B8: =COUNTIF(Locations!A:A,A8) -> 15
A9: GA | B9: =COUNTIF(Locations!A:A,A9) -> 5
A10: IA | B10: =COUNTIF(Locations!A:A,A10) -> 1
A11: ID | B11: =COUNTIF(Locations!A:A,A11) -> 4
A12: IL | B12: =COUNTIF(Locations!A:A,A12) -> 5
A13: IN | B13: =COUNTIF(Locations!A:A,A13) -> 10
... A45: WV | B45: =COUNTIF(Locations!A:A,A45) -> 7
A46: Total | B46: =SUM(B2:B45) -> 252
A48: Source: BoxDrop Direct store locator (boxdropdirect.com/pages/store-locator), pulled 2026-10-10.
